Workbook
Name Slicer_pickup_location: #N/A
Name Slicer_ride_status: #N/A

Sheet Clean Data
A1: ride_id | B1: timestamp | C1: pickup_location | D1: fare_amount | E1: driver_rating | F1: ride_status | G1: time_slot | I1: Data cleaning log
A2: RIDE1001 | B2: 46169.476 | C2: Mumbai_Thane | D2: 501.83 | E2: 3.47 | F2: COMPLETED | G2: =TEXT(RideData[[#This Row],[timestamp]],"hh:mm") -> 11:25 | I2: Source: Ride_Analytics_Raw_1000_Records.csv (1000 records).
A3: RIDE1002 | B3: 46169.476 | C3: Mumbai_Colaba | D3: 1770.4 | F3: COMPLETED | G3: =TEXT(RideData[[#This Row],[timestamp]],"hh:mm") -> 11:25 | I3: Exact duplicate rows removed: 0. Duplicate ride_id removed: 0.
A4: RIDE1003 | B4: 46169.476 | C4: Mumbai_Colaba | D4: 1726.32 | E4: 3.87 | F4: COMPLETED | G4: =TEXT(RideData[[#This Row],[timestamp]],"hh:mm") -> 11:25 | I4: Text fields trimmed; ride_status upper-cased; pickup_location and ride_status use consistent labels.
A5: RIDE1004 | B5: 46169.476 | C5: Mumbai_Colaba | D5: 0 | E5: 3.99 | F5: CANCELLED | G5: =TEXT(RideData[[#This Row],[timestamp]],"hh:mm") -> 11:25 | I5: timestamp converted to a real Excel date-time; fare_amount and driver_rating stored as numbers.
A6: RIDE1005 | B6: 46169.476 | C6: Mumbai_Thane | D6: 0 | E6: 4.07 | F6: NO_DRIVER_AVAILABLE | G6: =TEXT(RideData[[#This Row],[timestamp]],"hh:mm") -> 11:25 | I6: Blank driver_rating kept blank (109 rows) - not imputed, excluded from the average.
A7: RIDE1006 | B7: 46169.476 | C7: Mumbai_Bandra | D7: 0 | E7: 3.91 | F7: CANCELLED | G7: =TEXT(RideData[[#This Row],[timestamp]],"hh:mm") -> 11:25 | I7: fare_amount = 0 on cancelled / no-driver rides is a valid value and was kept.
A8: RIDE1007 | B8: 46169.476 | C8: Mumbai_Andheri | D8: 2542.08 | F8: COMPLETED | G8: =TEXT(RideData[[#This Row],[timestamp]],"hh:mm") -> 11:25 | I8: time_slot (HH:MM) is a formula column added only to group the trend PivotTable.
A9: RIDE1008 | B9: 46169.476 | C9: Mumbai_Colaba | D9: 0 | E9: 3.48 | F9: NO_DRIVER_AVAILABLE | G9: =TEXT(RideData[[#This Row],[timestamp]],"hh:mm") -> 11:25
A10: RIDE1009 | B10: 46169.476 | C10: Mumbai_Andheri | D10: 0 | E10: 4.68 | F10: CANCELLED | G10: =TEXT(RideData[[#This Row],[timestamp]],"hh:mm") -> 11:25
A11: RIDE1010 | B11: 46169.476 | C11: Mumbai_Colaba | D11: 2491.49 | E11: 3.52 | F11: COMPLETED | G11: =TEXT(RideData[[#This Row],[timestamp]],"hh:mm") -> 11:25
A12: RIDE1011 | B12: 46169.476 | C12: Mumbai_Andheri | D12: 1903.22 | E12: 4.33 | F12: COMPLETED | G12: =TEXT(RideData[[#This Row],[timestamp]],"hh:mm") -> 11:25
A13: RIDE1012 | B13: 46169.476 | C13: Mumbai_Colaba | D13: 2249.77 | E13: 3.71 | F13: COMPLETED | G13: =TEXT(RideData[[#This Row],[timestamp]],"hh:mm") -> 11:25
A14: RIDE1013 | B14: 46169.476 | C14: Mumbai_Colaba | D14: 0 | E14: 3.03 | F14: CANCELLED | G14: =TEXT(RideData[[#This Row],[timestamp]],"hh:mm") -> 11:25
A15: RIDE1014 | B15: 46169.476 | C15: Mumbai_Andheri | D15: 2055.68 | E15: 4.08 | F15: COMPLETED | G15: =TEXT(RideData[[#This Row],[timestamp]],"hh:mm") -> 11:25
A16: RIDE1015 | B16: 46169.476 | C16: Mumbai_Colaba | D16: 0 | E16: 4.13 | F16: CANCELLED | G16: =TEXT(RideData[[#This Row],[timestamp]],"hh:mm") -> 11:25
A17: RIDE1016 | B17: 46169.476 | C17: Mumbai_Andheri | D17: 1573.52 | E17: 4.43 | F17: COMPLETED | G17: =TEXT(RideData[[#This Row],[timestamp]],"hh:mm") -> 11:25
A18: RIDE1017 | B18: 46169.476 | C18: Mumbai_Andheri | D18: 1014.65 | F18: COMPLETED | G18: =TEXT(RideData[[#This Row],[timestamp]],"hh:mm") -> 11:25
A19: RIDE1018 | B19: 46169.476 | C19: Mumbai_Thane | D19: 1252.48 | E19: 3.5 | F19: COMPLETED | G19: =TEXT(RideData[[#This Row],[timestamp]],"hh:mm") -> 11:25
A20: RIDE1019 | B20: 46169.476 | C20: Mumbai_Colaba | D20: 1164.56 | E20: 3.48 | F20: COMPLETED | G20: =TEXT(RideData[[#This Row],[timestamp]],"hh:mm") -> 11:25
A21: RIDE1020 | B21: 46169.476 | C21: Mumbai_Andheri | D21: 0 | E21: 4.49 | F21: NO_DRIVER_AVAILABLE | G21: =TEXT(RideData[[#This Row],[timestamp]],"hh:mm") -> 11:25
A22: RIDE1021 | B22: 46169.476 | C22: Mumbai_Thane | D22: 1029.07 | E22: 5 | F22: COMPLETED | G22: =TEXT(RideData[[#This Row],[timestamp]],"hh:mm") -> 11:25
A23: RIDE1022 | B23: 46169.476 | C23: Mumbai_Andheri | D23: 589.86 | E23: 4.16 | F23: COMPLETED | G23: =TEXT(RideData[[#This Row],[timestamp]],"hh:mm") -> 11:25
A24: RIDE1023 | B24: 46169.476 | C24: Mumbai_Bandra | D24: 1098.01 | E24: 3.19 | F24: COMPLETED | G24: =TEXT(RideData[[#This Row],[timestamp]],"hh:mm") -> 11:25
A25: RIDE1024 | B25: 46169.476 | C25: Mumbai_Andheri | D25: 1463.23 | E25: 3.86 | F25: COMPLETED | G25: =TEXT(RideData[[#This Row],[timestamp]],"hh:mm") -> 11:25
A26: RIDE1025 | B26: 46169.476 | C26: Mumbai_Bandra | D26: 1501.97 | E26: 4.08 | F26: COMPLETED | G26: =TEXT(RideData[[#This Row],[timestamp]],"hh:mm") -> 11:25
A27: RIDE1026 | B27: 46169.476 | C27: Mumbai_Thane | D27: 0 | F27: CANCELLED | G27: =TEXT(RideData[[#This Row],[timestamp]],"hh:mm") -> 11:25
A28: RIDE1027 | B28: 46169.476 | C28: Mumbai_Bandra | D28: 0 | E28: 4.35 | F28: CANCELLED | G28: =TEXT(RideData[[#This Row],[timestamp]],"hh:mm") -> 11:25
A29: RIDE1028 | B29: 46169.476 | C29: Mumbai_Colaba | D29: 1140.09 | E29: 4.68 | F29: COMPLETED | G29: =TEXT(RideData[[#This Row],[timestamp]],"hh:mm") -> 11:25
A30: RIDE1029 | B30: 46169.476 | C30: Mumbai_Andheri | D30: 0 | E30: 4.22 | F30: NO_DRIVER_AVAILABLE | G30: =TEXT(RideData[[#This Row],[timestamp]],"hh:mm") -> 11:25
A31: RIDE1030 | B31: 46169.476 | C31: Mumbai_Colaba | D31: 3343.97 | F31: COMPLETED | G31: =TEXT(RideData[[#This Row],[timestamp]],"hh:mm") -> 11:25
A32: RIDE1031 | B32: 46169.476 | C32: Mumbai_Bandra | D32: 1109.11 | E32: 4.93 | F32: COMPLETED | G32: =TEXT(RideData[[#This Row],[timestamp]],"hh:mm") -> 11:25
A33: RIDE1032 | B33: 46169.476 | C33: Mumbai_Thane | D33: 2854.51 | E33: 3.75 | F33: COMPLETED | G33: =TEXT(RideData[[#This Row],[timestamp]],"hh:mm") -> 11:25
A34: RIDE1033 | B34: 46169.476 | C34: Mumbai_Thane | D34: 913.14 | E34: 3.4 | F34: COMPLETED | G34: =TEXT(RideData[[#This Row],[timestamp]],"hh:mm") -> 11:25
A35: RIDE1034 | B35: 46169.476 | C35: Mumbai_Thane | D35: 1601.65 | E35: 3.26 | F35: COMPLETED | G35: =TEXT(RideData[[#This Row],[timestamp]],"hh:mm") -> 11:25
A36: RIDE1035 | B36: 46169.476 | C36: Mumbai_Thane | D36: 2698.64 | E36: 4.22 | F36: COMPLETED | G36: =TEXT(RideData[[#This Row],[timestamp]],"hh:mm") -> 11:25
A37: RIDE1036 | B37: 46169.476 | C37: Mumbai_Thane | D37: 1865.49 | E37: 4.1 | F37: COMPLETED | G37: =TEXT(RideData[[#This Row],[timestamp]],"hh:mm") -> 11:25
A38: RIDE1037 | B38: 46169.476 | C38: Mumbai_Bandra | D38: 2628.19 | E38: 4.31 | F38: COMPLETED | G38: =TEXT(RideData[[#This Row],[timestamp]],"hh:mm") -> 11:25
A39: RIDE1038 | B39: 46169.476 | C39: Mumbai_Thane | D39: 0 | E39: 4.41 | F39: CANCELLED | G39: =TEXT(RideData[[#This Row],[timestamp]],"hh:mm") -> 11:25
A40: RIDE1039 | B40: 46169.476 | C40: Mumbai_Bandra | D40: 2043.94 | F40: COMPLETED | G40: =TEXT(RideData[[#This Row],[timestamp]],"hh:mm") -> 11:25
...

Sheet Pivot Table 1
A1: Ride Status Distribution (PivotTable ptStatus)
A3: Row Labels | B3: Rides | C3: % of Total
A4: COMPLETED | B4: 704 | C4: 0.704
A5: CANCELLED | B5: 222 | C5: 0.222
A6: NO_DRIVER_AVAILABLE | B6: 74 | C6: 0.074
A7: Grand Total | B7: 1000 | C7: 1

Sheet Pivot Table 2
A1: Rides by Pickup Location (PivotTable ptLocRides)
A3: Row Labels | B3: Rides
A4: Mumbai_Andheri | B4: 272
A5: Mumbai_Bandra | B5: 222
A6: Mumbai_Colaba | B6: 265
A7: Mumbai_Thane | B7: 241
A8: Grand Total | B8: 1000

Sheet Pivot Table 3
A1: Total Revenue by Pickup Location (PivotTable ptLocRevenue)
A3: Row Labels | B3: Total Revenue
A4: Mumbai_Andheri | B4: 305497.62
A5: Mumbai_Bandra | B5: 240807.78
A6: Mumbai_Colaba | B6: 275578.13
A7: Mumbai_Thane | B7: 237481.22
A8: Grand Total | B8: 1059364.8

Sheet Pivot Table 4
A1: Ride Trend Over Time (PivotTable ptTrend) - grand-total row also feeds the KPI cards
A3: Row Labels | B3: Rides | C3: Total Revenue | D3: Rating Sum | E3: Rated Rides
A4: 11:25 | B4: 89 | C4: 100665.22 | D4: 312.61 | E4: 77
A5: 11:30 | B5: 61 | C5: 67671.12 | D5: 205.36 | E5: 50
A6: 11:35 | B6: 79 | C6: 89000.55 | D6: 285.32 | E6: 70
A7: 11:40 | B7: 64 | C7: 62602.87 | D7: 230.18 | E7: 57
A8: 11:45 | B8: 79 | C8: 97134.6 | D8: 279.26 | E8: 71
A9: 11:50 | B9: 63 | C9: 76390.06 | D9: 225.23 | E9: 57
A10: 11:55 | B10: 73 | C10: 71041.66 | D10: 270.14 | E10: 68
A11: 12:00 | B11: 64 | C11: 52348.82 | D11: 231.9 | E11: 56
A12: 12:05 | B12: 67 | C12: 68865.45 | D12: 262.58 | E12: 64
A13: 12:10 | B13: 77 | C13: 85751.67 | D13: 251.56 | E13: 65
A14: 12:15 | B14: 51 | C14: 50699.1 | D14: 178.6 | E14: 45
A15: 12:20 | B15: 92 | C15: 88392.7 | D15: 339.78 | E15: 85
... A18: Grand Total | B18: 1000 | C18: 1059364.8 | D18: 3580.23 | E18: 891
A20: Slicers on the Dashboard filter this PivotTable together with the other three (one shared PivotCache).

Sheet Dashboard
U3: RIDE ANALYTICS DASHBOARD
E4: 🚗 | GJ4: 📅 | GS4: DATA PERIOD
GS9: =TEXT(MIN('Clean Data'!$B$2:$B$1001),"dd mmm yyyy")&" – "&TEXT(MAX('Clean Data'!$B$2:$B$1001),"dd mmm yyyy") -> 27 May 2026 – 27 May 2026
U10: Interactive rider insights • Use the filters to explore the data
C18: 🔻 FILTER PANEL
BU20: TOTAL RIDES | DQ20: COMPLETED RIDES | FH20: CANCELLED RIDES | HB20: NO DRIVER AVAILABLE
BG21: 👥 | DB21: ✅ | ET21: ❌ | GN21: 🕒
BU24: =GETPIVOTDATA("Rides",'Pivot Table 4'!$A$3) -> 1000 | DQ24: =IFERROR(GETPIVOTDATA("Rides",'Pivot Table 1'!$A$3,"ride_status","COMPLETED"),0) -> 704 | FH24: =IFERROR(GETPIVOTDATA("Rides",'Pivot Table 1'!$A$3,"ride_status","CANCELLED"),0) -> 222 | HB24: =IFERROR(GETPIVOTDATA("Rides",'Pivot Table 1'!$A$3,"ride_status","NO_DRIVER_AVAILABLE"),0) -> 74
E28: 📍 Pickup Location
BG38: 🪙 | BU38: TOTAL REVENUE | EX38: ⭐ | FL38: AVG. DRIVER RATING
BU42: =IFERROR(GETPIVOTDATA("Total Revenue",'Pivot Table 4'!$A$3),0) -> 1059364.8 | FL42: =IFERROR(GETPIVOTDATA("Rating Sum",'Pivot Table 4'!$A$3)/GETPIVOTDATA("Rated Rides",'Pivot Table 4'!$A$3),0) -> 4.0182155
E45: ☰ Ride Status
BE55: 📈 | BM55: Ride Trend Over Time | EU55: 🥧 | FC55: Ride Status Distribution
E65: ℹ️
N66: DATA QUALITY
N71: =(GETPIVOTDATA("Rides",'Pivot Table 4'!$A$3)-GETPIVOTDATA("Rated Rides",'Pivot Table 4'!$A$3))&" driver ratings are blank and are excluded from the average rating." -> 109 driver ratings are blank and are excluded from the average rating.
E86: 📊 | N86: KEY INSIGHTS
Q93: =IFERROR(IFERROR(GETPIVOTDATA("Rides",'Pivot Table 1'!$A$3,"ride_status","COMPLETED"),0)/GETPIVOTDATA("Rides",'Pivot Table 4'!$A$3),0) -> 0.704
F94: ✅
Q99: Rides completed
BE104: 📊 | BM104: Rides by Pickup Location | ER104: 🪙 | FA104: Total Revenue by Pickup Location
F106: ❌ | Q106: =IFERROR(IFERROR(GETPIVOTDATA("Rides",'Pivot Table 1'!$A$3,"ride_status","CANCELLED"),0)/GETPIVOTDATA("Rides",'Pivot Table 4'!$A$3),0) -> 0.222
Q111: Rides cancelled
F118: 📈 | Q118: =IFERROR(INDEX('Pivot Table 3'!$A$4:$A$7,MATCH(MAX('Pivot Table 3'!$B$4:$B$7),'Pivot Table 3'!$B$4:$B$7,0)),"-") -> Mumbai_Andheri
Q123: Highest revenue location
Q130: =IFERROR(GETPIVOTDATA("Rides",'Pivot Table 4'!$A$3)-GETPIVOTDATA("Rated Rides",'Pivot Table 4'!$A$3),0) -> 109
F131: 👥
Q135: Driver ratings excluded due to missing values
